<?xml version="1.0"?><robot name="pepe">
	<link name="0">
		<visual>
			<geometry>
				<cylinder length="1.5719694036168639" radius="0.9999"/>
			</geometry>
		</visual>
		<collision>
			<geometry>
				<cylinder length="1.5719694036168639" radius="0.9999"/>
			</geometry>
		</collision>
		<inertial>
			<mass value="4.937499881949529"/>
			<inertia ixx="0.03" iyy="0.03" izz="0.03" ixy="0" ixz="0" iyx="0"/>
		</inertial>
	</link>
	<link name="11">
		<visual>
			<geometry>
				<cylinder length="1.371969403616864" radius="0.9999"/>
			</geometry>
		</visual>
		<collision>
			<geometry>
				<cylinder length="1.371969403616864" radius="0.9999"/>
			</geometry>
		</collision>
		<inertial>
			<mass value="4.309307008654529"/>
			<inertia ixx="0.03" iyy="0.03" izz="0.03" ixy="0" ixz="0" iyx="0"/>
		</inertial>
	</link>
	<link name="12">
		<visual>
			<geometry>
				<cylinder length="1.371969403616864" radius="0.9999"/>
			</geometry>
		</visual>
		<collision>
			<geometry>
				<cylinder length="1.371969403616864" radius="0.9999"/>
			</geometry>
		</collision>
		<inertial>
			<mass value="4.309307008654529"/>
			<inertia ixx="0.03" iyy="0.03" izz="0.03" ixy="0" ixz="0" iyx="0"/>
		</inertial>
	</link>
	<joint name="11_to_0" type="revolute">
		<parent link="0"/>
		<child link="11"/>
		<axis xyz="1 0 0"/>
		<limit effort="1" upper="-3.1415" lower="3.1415" velocity="1"/>
		<origin rpy="4.05418725368378 1.7107464802685615 3.2037363709312974" xyz="0.5957727693958238 0.963333276953687 0.9703223273250453"/>
	</joint>
	<joint name="12_to_0" type="revolute">
		<parent link="0"/>
		<child link="12"/>
		<axis xyz="1 0 0"/>
		<limit effort="1" upper="-3.1415" lower="3.1415" velocity="1"/>
		<origin rpy="6.081280880525671 1.7107464802685615 3.2037363709312974" xyz="0.5957727693958238 0.963333276953687 0.9703223273250453"/>
	</joint>
</robot>
